Workbook

Sheet Übersicht
A1: Depot-Look-through: Einzelaktien inklusive Fonds und ETFs
A2: Depotwerte: 17.07.2026 | Fonds-/ETF-Bestände: 10.–16.07.2026 | Unternehmen nach offensichtlichen Aktienklassen konsolidiert
A4: Kennzahl | B4: Wert
A5: Gesamtvermögen | B5: 110400.89
A6: Direkte Einzelaktien | B6: 52033.96
A7: Indirekt aufgelöste Einzelaktien | B7: 43140.442
A8: Aufgelöste Aktienexposure gesamt | B8: 95174.402
A9: Nicht aufgelöst / keine Einzelaktien | B9: 15226.488
A10: Anzahl konsolidierter Unternehmen | B10: 1288
A12: Rang | B12: Unternehmen | C12: Sektor | D12: Direkt (€) | E12: Indirekt (€) | F12: Gesamt-Exposure (€) | G12: Anteil Gesamtvermögen | H12: Aktienfonds (€) | I12: Global Titans (€) | J12: Technologiefonds 60% (€) | K12: MSCI World (€) | L12: World Value (€)
A13: 1 | B13: Berkshire Hathaway | C13: Financials | D13: 23600.5 | E13: 578.53782 | F13: 24179.038 | G13: 0.21901126 | H13: 552.97811 | I13: 0 | J13: 0 | K13: 25.559712 | L13: 0
A14: 2 | B14: Nvidia | C14: Information Technology | D14: 4430.5 | E14: 1929.2743 | F14: 6359.7743 | G14: 0.057606187 | H14: 601.46406 | I14: 1061.7518 | J14: 86.804207 | K14: 179.2543 | L14: 0
A15: 3 | B15: Alphabet | C15: Communication | D15: 3328.6 | E15: 1801.5608 | F15: 5130.1608 | G15: 0.046468474 | H15: 555.08205 | I15: 1024.4973 | J15: 83.420928 | K15: 138.56054 | L15: 0
A16: 4 | B16: Allianz | C16: Financials | D16: 4210 | E16: 580.0219 | F16: 4790.0219 | G16: 0.04338753 | H16: 573.29566 | I16: 0 | J16: 0 | K16: 6.72624 | L16: 0
A17: 5 | B17: AMD | C17: Information Technology | D17: 3896.55 | E17: 697.78379 | F17: 4594.3338 | G17: 0.041615007 | H17: 573.30194 | I17: 0 | J17: 93.877466 | K17: 30.604392 | L17: 0
A18: 6 | B18: Microsoft | C18: Information Technology | D18: 2410.1 | E18: 1806.3823 | F18: 4216.4823 | G18: 0.038192467 | H18: 573.75232 | I18: 1036.472 | J18: 90.219784 | K18: 105.93828 | L18: 0
A19: 7 | B19: Apple | C19: Information Technology | D19: 1458.25 | E19: 2068.3081 | F19: 3526.5581 | G19: 0.031943203 | H19: 615.1246 | I19: 1173.5151 | J19: 96.714621 | K19: 182.95373 | L19: 0
A20: 8 | B20: Eli Lilly | C20: Health Care | D20: 2060.8 | E20: 933.23275 | F20: 2994.0328 | G20: 0.027119643 | H20: 536.35595 | I20: 361.90035 | J20: 0 | K20: 34.976448 | L20: 0
A21: 9 | B21: TSMC | C21: Information Technology | D21: 696 | E21: 1324.8169 | F21: 2020.8169 | G21: 0.018304353 | H21: 529.24686 | I21: 723.8007 | J21: 71.769335 | K21: 0 | L21: 0
A22: 10 | B22: Siemens | D22: 1851.5 | E22: 80.610658 | F22: 1932.1107 | G22: 0.017500861 | H22: 0 | I22: 0 | J22: 80.610658 | K22: 0 | L22: 0
A23: 11 | B23: HSBC | C23: Financials | D23: 1702.16 | E23: 160.01699 | F23: 1862.177 | G23: 0.016867409 | H23: 0 | I23: 135.71263 | J23: 0 | K23: 12.779856 | L23: 11.524504
A24: 12 | B24: Amazon | C24: Consumer Discretionary | D24: 0 | E24: 1705.6751 | F24: 1705.6751 | G24: 0.015449831 | H24: 567.84793 | I24: 959.30204 | J24: 88.057173 | K24: 90.467928 | L24: 0
A25: 13 | B25: Micron Technology | C25: Information Technology | D25: 1492.2 | E25: 186.48856 | F25: 1678.6886 | G25: 0.01520539 | H25: 0 | I25: 0 | J25: 0 | K25: 35.985384 | L25: 150.50318
A26: 14 | B26: Linde | C26: Materials | D26: 896.8 | E26: 103.54706 | F26: 1000.3471 | G26: 0.0090610416 | H26: 0 | I26: 94.466636 | J26: 0 | K26: 9.080424 | L26: 0
A27: 15 | B27: ASML | C27: Information Technology | D27: 0 | E27: 931.18791 | F27: 931.18791 | G27: 0.0084346051 | H27: 548.22921 | I27: 278.07784 | J27: 78.312211 | K27: 26.568648 | L27: 0
A28: 16 | B28: Broadcom | C28: Information Technology | D28: 0 | E28: 840.4393 | F28: 840.4393 | G28: 0.0076126135 | H28: 0 | I28: 694.52935 | J28: 83.019604 | K28: 62.890344 | L28: 0
A29: 17 | B29: Visa | C29: Financials | D29: 0 | E29: 822.22896 | F29: 822.22896 | G29: 0.007447666 | H29: 561.19738 | I29: 238.16236 | J29: 0 | K29: 22.869216 | L29: 0
A30: 18 | B30: Netflix | C30: Communication | D30: 0 | E30: 766.88359 | F30: 766.88359 | G30: 0.0069463533 | H30: 545.7117 | I30: 122.40747 | J30: 86.993496 | K30: 11.77092 | L30: 0
A31: 19 | B31: Mastercard | C31: Financials | D31: 0 | E31: 760.81545 | F31: 760.81545 | G31: 0.0068913887 | H31: 569.70225 | I31: 174.2976 | J31: 0 | K31: 16.8156 | L31: 0
A32: 20 | B32: SAP | C32: Information Technology | D32: 0 | E32: 714.6136 | F32: 714.6136 | G32: 0.0064728971 | H32: 560.15032 | I32: 62.534252 | J32: 85.875411 | K32: 6.053616 | L32: 0
A33: 21 | B33: T-Mobile US | D33: 0 | E33: 688.23899 | F33: 688.23899 | G33: 0.0062339985 | H33: 592.34453 | I33: 0 | J33: 95.894458 | K33: 0 | L33: 0
A34: 22 | B34: Caterpillar | C34: Industrials | D34: 0 | E34: 687.87404 | F34: 687.87404 | G34: 0.0062306929 | H34: 514.4086 | I34: 158.3314 | J34: 0 | K34: 15.13404 | L34: 0
A35: 23 | B35: McDonald's | C35: Consumer Discretionary | D35: 0 | E35: 647.32463 | F35: 647.32463 | G35: 0.0058634005 | H35: 564.08635 | I35: 75.839412 | J35: 0 | K35: 7.398864 | L35: 0
A36: 24 | B36: Booking Holdings | C36: Consumer Discretionary | D36: 0 | E36: 635.87322 | F36: 635.87322 | G36: 0.0057596747 | H36: 543.19522 | I36: 0 | J36: 86.960697 | K36: 5.717304 | L36: 0
A37: 25 | B37: Nasdaq Inc. | C37: Financials | D37: 0 | E37: 631.04708 | F37: 631.04708 | G37: 0.0057159601 | H37: 629.36552 | I37: 0 | J37: 0 | K37: 1.68156 | L37: 0
A39: Wichtige Abgrenzung: Beim boerse.de-Technologiefonds sind nur die öffentlich vollständig aufgeführten 60% des Basisportfolios auf Unternehmen verteilt. Das 40%-Darwin-Portfolio mit mehr als 500 Technologieaktien ist nicht vollständig öffentlich auflösbar. Die dort enthaltenen Unternehmensanteile fehlen daher in den Einzelwerten.

Sheet Alle Unternehmen
A1: Rang | B1: Unternehmen | C1: Sektor | D1: Direktbestand (€) | E1: boerse.de-Aktienfonds (€) | F1: Global Titans 50 (€) | G1: boerse.de-Technologiefonds – öffentl. 60% (€) | H1: MSCI World (€) | I1: World Value (€) | J1: Indirekt gesamt (€) | K1: Gesamt-Exposure (€) | L1: Anteil Gesamtvermögen | M1: Enthalten in | N1: Quellen
A2: 1 | B2: Berkshire Hathaway | C2: Financials | D2: 23600.5 | E2: 552.97811 | F2: 0 | G2: 0 | H2: 25.559712 | I2: 0 | J2: =SUM(E2:I2) -> 578.53782 | K2: =D2+J2 -> 24179.038 | L2: =K2/'Quellen & Annahmen'!$B$2 -> 0.21901126 | M2: Direkt; boerse.de-Aktienfonds; MSCI World | N2: Nutzerangaben im Chat; https://www.boerse-aktienfonds.de/; https://www.ishares.com/ch/individual/en/products/251882/ishares-msci-world-ucits-etf-acc-fund
A3: 2 | B3: Nvidia | C3: Information Technology | D3: 4430.5 | E3: 601.46406 | F3: 1061.7518 | G3: 86.804207 | H3: 179.2543 | I3: 0 | J3: =SUM(E3:I3) -> 1929.2743 | K3: =D3+J3 -> 6359.7743 | L3: =K3/'Quellen & Annahmen'!$B$2 -> 0.057606187 | M3: Direkt; boerse.de-Aktienfonds; Global Titans 50; boerse.de-Technologiefonds (60% offengelegt); MSCI World | N3: Nutzerangaben im Chat; https://www.boerse-aktienfonds.de/; https://www.ishares.com/ch/professionals/en/products/251769/ishares-dow-jones-global-titans-50-ucits-etf-de-fund; https://www.boerse-technologiefonds.de/; https://www.ishares.com/ch/individual/en/products/251882/ishares-msci-world-ucits-etf-acc-fund
A4: 3 | B4: Alphabet | C4: Communication | D4: 3328.6 | E4: 555.08205 | F4: 1024.4973 | G4: 83.420928 | H4: 138.56054 | I4: 0 | J4: =SUM(E4:I4) -> 1801.5608 | K4: =D4+J4 -> 5130.1608 | L4: =K4/'Quellen & Annahmen'!$B$2 -> 0.046468474 | M4: Direkt; boerse.de-Aktienfonds; Global Titans 50; boerse.de-Technologiefonds (60% offengelegt); MSCI World | N4: Nutzerangaben im Chat; https://www.boerse-aktienfonds.de/; https://www.ishares.com/ch/professionals/en/products/251769/ishares-dow-jones-global-titans-50-ucits-etf-de-fund; https://www.boerse-technologiefonds.de/; https://www.ishares.com/ch/individual/en/products/251882/ishares-msci-world-ucits-etf-acc-fund
A5: 4 | B5: Allianz | C5: Financials | D5: 4210 | E5: 573.29566 | F5: 0 | G5: 0 | H5: 6.72624 | I5: 0 | J5: =SUM(E5:I5) -> 580.0219 | K5: =D5+J5 -> 4790.0219 | L5: =K5/'Quellen & Annahmen'!$B$2 -> 0.04338753 | M5: Direkt; boerse.de-Aktienfonds; MSCI World | N5: Nutzerangaben im Chat; https://www.boerse-aktienfonds.de/; https://www.ishares.com/ch/individual/en/products/251882/ishares-msci-world-ucits-etf-acc-fund
A6: 5 | B6: AMD | C6: Information Technology | D6: 3896.55 | E6: 573.30194 | F6: 0 | G6: 93.877466 | H6: 30.604392 | I6: 0 | J6: =SUM(E6:I6) -> 697.78379 | K6: =D6+J6 -> 4594.3338 | L6: =K6/'Quellen & Annahmen'!$B$2 -> 0.041615007 | M6: Direkt; boerse.de-Aktienfonds; boerse.de-Technologiefonds (60% offengelegt); MSCI World | N6: Nutzerangaben im Chat; https://www.boerse-aktienfonds.de/; https://www.boerse-technologiefonds.de/; https://www.ishares.com/ch/individual/en/products/251882/ishares-msci-world-ucits-etf-acc-fund
A7: 6 | B7: Microsoft | C7: Information Technology | D7: 2410.1 | E7: 573.75232 | F7: 1036.472 | G7: 90.219784 | H7: 105.93828 | I7: 0 | J7: =SUM(E7:I7) -> 1806.3823 | K7: =D7+J7 -> 4216.4823 | L7: =K7/'Quellen & Annahmen'!$B$2 -> 0.038192467 | M7: Direkt; boerse.de-Aktienfonds; Global Titans 50; boerse.de-Technologiefonds (60% offengelegt); MSCI World | N7: Nutzerangaben im Chat; https://www.boerse-aktienfonds.de/; https://www.ishares.com/ch/professionals/en/products/251769/ishares-dow-jones-global-titans-50-ucits-etf-de-fund; https://www.boerse-technologiefonds.de/; https://www.ishares.com/ch/individual/en/products/251882/ishares-msci-world-ucits-etf-acc-fund
A8: 7 | B8: Apple | C8: Information Technology | D8: 1458.25 | E8: 615.1246 | F8: 1173.5151 | G8: 96.714621 | H8: 182.95373 | I8: 0 | J8: =SUM(E8:I8) -> 2068.3081 | K8: =D8+J8 -> 3526.5581 | L8: =K8/'Quellen & Annahmen'!$B$2 -> 0.031943203 | M8: Direkt; boerse.de-Aktienfonds; Global Titans 50; boerse.de-Technologiefonds (60% offengelegt); MSCI World | N8: Nutzerangaben im Chat; https://www.boerse-aktienfonds.de/; https://www.ishares.com/ch/professionals/en/products/251769/ishares-dow-jones-global-titans-50-ucits-etf-de-fund; https://www.boerse-technologiefonds.de/; https://www.ishares.com/ch/individual/en/products/251882/ishares-msci-world-ucits-etf-acc-fund
A9: 8 | B9: Eli Lilly | C9: Health Care | D9: 2060.8 | E9: 536.35595 | F9: 361.90035 | G9: 0 | H9: 34.976448 | I9: 0 | J9: =SUM(E9:I9) -> 933.23275 | K9: =D9+J9 -> 2994.0328 | L9: =K9/'Quellen & Annahmen'!$B$2 -> 0.027119643 | M9: Direkt; boerse.de-Aktienfonds; Global Titans 50; MSCI World | N9: Nutzerangaben im Chat; https://www.boerse-aktienfonds.de/; https://www.ishares.com/ch/professionals/en/products/251769/ishares-dow-jones-global-titans-50-ucits-etf-de-fund; https://www.ishares.com/ch/individual/en/products/251882/ishares-msci-world-ucits-etf-acc-fund
A10: 9 | B10: TSMC | C10: Information Technology | D10: 696 | E10: 529.24686 | F10: 723.8007 | G10: 71.769335 | H10: 0 | I10: 0 | J10: =SUM(E10:I10) -> 1324.8169 | K10: =D10+J10 -> 2020.8169 | L10: =K10/'Quellen & Annahmen'!$B$2 -> 0.018304353 | M10: Direkt; boerse.de-Aktienfonds; Global Titans 50; boerse.de-Technologiefonds (60% offengelegt) | N10: Nutzerangaben im Chat; https://www.boerse-aktienfonds.de/; https://www.ishares.com/ch/professionals/en/products/251769/ishares-dow-jones-global-titans-50-ucits-etf-de-fund; https://www.boerse-technologiefonds.de/
A11: 10 | B11: Siemens | D11: 1851.5 | E11: 0 | F11: 0 | G11: 80.610658 | H11: 0 | I11: 0 | J11: =SUM(E11:I11) -> 80.610658 | K11: =D11+J11 -> 1932.1107 | L11: =K11/'Quellen & Annahmen'!$B$2 -> 0.017500861 | M11: Direkt; boerse.de-Technologiefonds (60% offengelegt) | N11: Nutzerangaben im Chat; https://www.boerse-technologiefonds.de/
A12: 11 | B12: HSBC | C12: Financials | D12: 1702.16 | E12: 0 | F12: 135.71263 | G12: 0 | H12: 12.779856 | I12: 11.524504 | J12: =SUM(E12:I12) -> 160.01699 | K12: =D12+J12 -> 1862.177 | L12: =K12/'Quellen & Annahmen'!$B$2 -> 0.016867409 | M12: Direkt; Global Titans 50; MSCI World; World Value | N12: Nutzerangaben im Chat; https://www.ishares.com/ch/professionals/en/products/251769/ishares-dow-jones-global-titans-50-ucits-etf-de-fund; https://www.ishares.com/ch/individual/en/products/251882/ishares-msci-world-ucits-etf-acc-fund; https://www.ishares.com/ch/individual/en/products/270048/ishares-msci-world-value-factor-ucits-etf
A13: 12 | B13: Amazon | C13: Consumer Discretionary | D13: 0 | E13: 567.84793 | F13: 959.30204 | G13: 88.057173 | H13: 90.467928 | I13: 0 | J13: =SUM(E13:I13) -> 1705.6751 | K13: =D13+J13 -> 1705.6751 | L13: =K13/'Quellen & Annahmen'!$B$2 -> 0.015449831 | M13: boerse.de-Aktienfonds; Global Titans 50; boerse.de-Technologiefonds (60% offengelegt); MSCI World | N13: https://www.boerse-aktienfonds.de/; https://www.ishares.com/ch/professionals/en/products/251769/ishares-dow-jones-global-titans-50-ucits-etf-de-fund; https://www.boerse-technologiefonds.de/; https://www.ishares.com/ch/individual/en/products/251882/ishares-msci-world-ucits-etf-acc-fund
A14: 13 | B14: Micron Technology | C14: Information Technology | D14: 1492.2 | E14: 0 | F14: 0 | G14: 0 | H14: 35.985384 | I14: 150.50318 | J14: =SUM(E14:I14) -> 186.48856 | K14: =D14+J14 -> 1678.6886 | L14: =K14/'Quellen & Annahmen'!$B$2 -> 0.01520539 | M14: Direkt; MSCI World; World Value | N14: Nutzerangaben im Chat; https://www.ishares.com/ch/individual/en/products/251882/ishares-msci-world-ucits-etf-acc-fund; https://www.ishares.com/ch/individual/en/products/270048/ishares-msci-world-value-factor-ucits-etf
A15: 14 | B15: Linde | C15: Materials | D15: 896.8 | E15: 0 | F15: 94.466636 | G15: 0 | H15: 9.080424 | I15: 0 | J15: =SUM(E15:I15) -> 103.54706 | K15: =D15+J15 -> 1000.3471 | L15: =K15/'Quellen & Annahmen'!$B$2 -> 0.0090610416 | M15: Direkt; Global Titans 50; MSCI World | N15: Nutzerangaben im Chat; https://www.ishares.com/ch/professionals/en/products/251769/ishares-dow-jones-global-titans-50-ucits-etf-de-fund; https://www.ishares.com/ch/individual/en/products/251882/ishares-msci-world-ucits-etf-acc-fund
A16: 15 | B16: ASML | C16: Information Technology | D16: 0 | E16: 548.22921 | F16: 278.07784 | G16: 78.312211 | H16: 26.568648 | I16: 0 | J16: =SUM(E16:I16) -> 931.18791 | K16: =D16+J16 -> 931.18791 | L16: =K16/'Quellen & Annahmen'!$B$2 -> 0.0084346051 | M16: boerse.de-Aktienfonds; Global Titans 50; boerse.de-Technologiefonds (60% offengelegt); MSCI World | N16: https://www.boerse-aktienfonds.de/; https://www.ishares.com/ch/professionals/en/products/251769/ishares-dow-jones-global-titans-50-ucits-etf-de-fund; https://www.boerse-technologiefonds.de/; https://www.ishares.com/ch/individual/en/products/251882/ishares-msci-world-ucits-etf-acc-fund
A17: 16 | B17: Broadcom | C17: Information Technology | D17: 0 | E17: 0 | F17: 694.52935 | G17: 83.019604 | H17: 62.890344 | I17: 0 | J17: =SUM(E17:I17) -> 840.4393 | K17: =D17+J17 -> 840.4393 | L17: =K17/'Quellen & Annahmen'!$B$2 -> 0.0076126135 | M17: Global Titans 50; boerse.de-Technologiefonds (60% offengelegt); MSCI World | N17: https://www.ishares.com/ch/professionals/en/products/251769/ishares-dow-jones-global-titans-50-ucits-etf-de-fund; https://www.boerse-technologiefonds.de/; https://www.ishares.com/ch/individual/en/products/251882/ishares-msci-world-ucits-etf-acc-fund
A18: 17 | B18: Visa | C18: Financials | D18: 0 | E18: 561.19738 | F18: 238.16236 | G18: 0 | H18: 22.869216 | I18: 0 | J18: =SUM(E18:I18) -> 822.22896 | K18: =D18+J18 -> 822.22896 | L18: =K18/'Quellen & Annahmen'!$B$2 -> 0.007447666 | M18: boerse.de-Aktienfonds; Global Titans 50; MSCI World | N18: https://www.boerse-aktienfonds.de/; https://www.ishares.com/ch/professionals/en/products/251769/ishares-dow-jones-global-titans-50-ucits-etf-de-fund; https://www.ishares.com/ch/individual/en/products/251882/ishares-msci-world-ucits-etf-acc-fund
A19: 18 | B19: Netflix | C19: Communication | D19: 0 | E19: 545.7117 | F19: 122.40747 | G19: 86.993496 | H19: 11.77092 | I19: 0 | J19: =SUM(E19:I19) -> 766.88359 | K19: =D19+J19 -> 766.88359 | L19: =K19/'Quellen & Annahmen'!$B$2 -> 0.0069463533 | M19: boerse.de-Aktienfonds; Global Titans 50; boerse.de-Technologiefonds (60% offengelegt); MSCI World | N19: https://www.boerse-aktienfonds.de/; https://www.ishares.com/ch/professionals/en/products/251769/ishares-dow-jones-global-titans-50-ucits-etf-de-fund; https://www.boerse-technologiefonds.de/; https://www.ishares.com/ch/individual/en/products/251882/ishares-msci-world-ucits-etf-acc-fund
A20: 19 | B20: Mastercard | C20: Financials | D20: 0 | E20: 569.70225 | F20: 174.2976 | G20: 0 | H20: 16.8156 | I20: 0 | J20: =SUM(E20:I20) -> 760.81545 | K20: =D20+J20 -> 760.81545 | L20: =K20/'Quellen & Annahmen'!$B$2 -> 0.0068913887 | M20: boerse.de-Aktienfonds; Global Titans 50; MSCI World | N20: https://www.boerse-aktienfonds.de/; https://www.ishares.com/ch/professionals/en/products/251769/ishares-dow-jones-global-titans-50-ucits-etf-de-fund; https://www.ishares.com/ch/individual/en/products/251882/ishares-msci-world-ucits-etf-acc-fund
A21: 20 | B21: SAP | C21: Information Technology | D21: 0 | E21: 560.15032 | F21: 62.534252 | G21: 85.875411 | H21: 6.053616 | I21: 0 | J21: =SUM(E21:I21) -> 714.6136 | K21: =D21+J21 -> 714.6136 | L21: =K21/'Quellen & Annahmen'!$B$2 -> 0.0064728971 | M21: boerse.de-Aktienfonds; Global Titans 50; boerse.de-Technologiefonds (60% offengelegt); MSCI World | N21: https://www.boerse-aktienfonds.de/; https://www.ishares.com/ch/professionals/en/products/251769/ishares-dow-jones-global-titans-50-ucits-etf-de-fund; https://www.boerse-technologiefonds.de/; https://www.ishares.com/ch/individual/en/products/251882/ishares-msci-world-ucits-etf-acc-fund
A22: 21 | B22: T-Mobile US | D22: 0 | E22: 592.34453 | F22: 0 | G22: 95.894458 | H22: 0 | I22: 0 | J22: =SUM(E22:I22) -> 688.23899 | K22: =D22+J22 -> 688.23899 | L22: =K22/'Quellen & Annahmen'!$B$2 -> 0.0062339985 | M22: boerse.de-Aktienfonds; boerse.de-Technologiefonds (60% offengelegt) | N22: https://www.boerse-aktienfonds.de/; https://www.boerse-technologiefonds.de/
A23: 22 | B23: Caterpillar | C23: Industrials | D23: 0 | E23: 514.4086 | F23: 158.3314 | G23: 0 | H23: 15.13404 | I23: 0 | J23: =SUM(E23:I23) -> 687.87404 | K23: =D23+J23 -> 687.87404 | L23: =K23/'Quellen & Annahmen'!$B$2 -> 0.0062306929 | M23: boerse.de-Aktienfonds; Global Titans 50; MSCI World | N23: https://www.boerse-aktienfonds.de/; https://www.ishares.com/ch/professionals/en/products/251769/ishares-dow-jones-global-titans-50-ucits-etf-de-fund; https://www.ishares.com/ch/individual/en/products/251882/ishares-msci-world-ucits-etf-acc-fund
A24: 23 | B24: McDonald's | C24: Consumer Discretionary | D24: 0 | E24: 564.08635 | F24: 75.839412 | G24: 0 | H24: 7.398864 | I24: 0 | J24: =SUM(E24:I24) -> 647.32463 | K24: =D24+J24 -> 647.32463 | L24: =K24/'Quellen & Annahmen'!$B$2 -> 0.0058634005 | M24: boerse.de-Aktienfonds; Global Titans 50; MSCI World | N24: https://www.boerse-aktienfonds.de/; https://www.ishares.com/ch/professionals/en/products/251769/ishares-dow-jones-global-titans-50-ucits-etf-de-fund; https://www.ishares.com/ch/individual/en/products/251882/ishares-msci-world-ucits-etf-acc-fund
A25: 24 | B25: Booking Holdings | C25: Consumer Discretionary | D25: 0 | E25: 543.19522 | F25: 0 | G25: 86.960697 | H25: 5.717304 | I25: 0 | J25: =SUM(E25:I25) -> 635.87322 | K25: =D25+J25 -> 635.87322 | L25: =K25/'Quellen & Annahmen'!$B$2 -> 0.0057596747 | M25: boerse.de-Aktienfonds; boerse.de-Technologiefonds (60% offengelegt); MSCI World | N25: https://www.boerse-aktienfonds.de/; https://www.boerse-technologiefonds.de/; https://www.ishares.com/ch/individual/en/products/251882/ishares-msci-world-ucits-etf-acc-fund
A26: 25 | B26: Nasdaq Inc. | C26: Financials | D26: 0 | E26: 629.36552 | F26: 0 | G26: 0 | H26: 1.68156 | I26: 0 | J26: =SUM(E26:I26) -> 631.04708 | K26: =D26+J26 -> 631.04708 | L26: =K26/'Quellen & Annahmen'!$B$2 -> 0.0057159601 | M26: boerse.de-Aktienfonds; MSCI World | N26: https://www.boerse-aktienfonds.de/; https://www.ishares.com/ch/individual/en/products/251882/ishares-msci-world-ucits-etf-acc-fund
A27: 26 | B27: Meta Platforms | C27: Communication | D27: 0 | E27: 0 | F27: 572.12188 | G27: 0 | H27: 54.482544 | I27: 0 | J27: =SUM(E27:I27) -> 626.60442 | K27: =D27+J27 -> 626.60442 | L27: =K27/'Quellen & Annahmen'!$B$2 -> 0.005675719 | M27: Global Titans 50; MSCI World | N27: https://www.ishares.com/ch/professionals/en/products/251769/ishares-dow-jones-global-titans-50-ucits-etf-de-fund; https://www.ishares.com/ch/individual/en/products/251882/ishares-msci-world-ucits-etf-acc-fund
A28: 27 | B28: LVMH | C28: Consumer Discretionary | D28: 0 | E28: 558.67546 | F28: 57.212188 | G28: 0 | H28: 5.380992 | I28: 0 | J28: =SUM(E28:I28) -> 621.26864 | K28: =D28+J28 -> 621.26864 | L28: =K28/'Quellen & Annahmen'!$B$2 -> 0.0056273879 | M28: boerse.de-Aktienfonds; Global Titans 50; MSCI World | N28: https://www.boerse-aktienfonds.de/; https://www.ishares.com/ch/professionals/en/products/251769/ishares-dow-jones-global-titans-50-ucits-etf-de-fund; https://www.ishares.com/ch/individual/en/products/251882/ishares-msci-world-ucits-etf-acc-fund
A29: 28 | B29: Amphenol | C29: Information Technology | D29: 0 | E29: 531.62759 | F29: 0 | G29: 72.441105 | H29: 7.062552 | I29: 0 | J29: =SUM(E29:I29) -> 611.13125 | K29: =D29+J29 -> 611.13125 | L29: =K29/'Quellen & Annahmen'!$B$2 -> 0.0055355645 | M29: boerse.de-Aktienfonds; boerse.de-Technologiefonds (60% offengelegt); MSCI World | N29: https://www.boerse-aktienfonds.de/; https://www.boerse-technologiefonds.de/; https://www.ishares.com/ch/individual/en/products/251882/ishares-msci-world-ucits-etf-acc-fund
A30: 29 | B30: BlackRock | C30: Financials | D30: 0 | E30: 598.71983 | F30: 0 | G30: 0 | H30: 6.053616 | I30: 0 | J30: =SUM(E30:I30) -> 604.77345 | K30: =D30+J30 -> 604.77345 | L30: =K30/'Quellen & Annahmen'!$B$2 -> 0.0054779762 | M30: boerse.de-Aktienfonds; MSCI World | N30: https://www.boerse-aktienfonds.de/; https://www.ishares.com/ch/individual/en/products/251882/ishares-msci-world-ucits-etf-acc-fund
A31: 30 | B31: MSCI Inc. | C31: Financials | D31: 0 | E31: 591.31512 | F31: 0 | G31: 0 | H31: 1.68156 | I31: 0 | J31: =SUM(E31:I31) -> 592.99668 | K31: =D31+J31 -> 592.99668 | L31: =K31/'Quellen & Annahmen'!$B$2 -> 0.0053713035 | M31: boerse.de-Aktienfonds; MSCI World | N31: https://www.boerse-aktienfonds.de/; https://www.ishares.com/ch/individual/en/products/251882/ishares-msci-world-ucits-etf-acc-fund
A32: 31 | B32: Cintas | C32: Industrials | D32: 0 | E32: 583.5963 | F32: 0 | G32: 0 | H32: 2.690496 | I32: 0 | J32: =SUM(E32:I32) -> 586.2868 | K32: =D32+J32 -> 586.2868 | L32: =K32/'Quellen & Annahmen'!$B$2 -> 0.005310526 | M32: boerse.de-Aktienfonds; MSCI World | N32: https://www.boerse-aktienfonds.de/; https://www.ishares.com/ch/individual/en/products/251882/ishares-msci-world-ucits-etf-acc-fund
A33: 32 | B33: S&P Global | C33: Financials | D33: 0 | E33: 578.83349 | F33: 0 | G33: 0 | H33: 5.380992 | I33: 0 | J33: =SUM(E33:I33) -> 584.21448 | K33: =D33+J33 -> 584.21448 | L33: =K33/'Quellen & Annahmen'!$B$2 -> 0.0052917552 | M33: boerse.de-Aktienfonds; MSCI World | N33: https://www.boerse-aktienfonds.de/; https://www.ishares.com/ch/individual/en/products/251882/ishares-msci-world-ucits-etf-acc-fund
A34: 33 | B34: Waste Management | C34: Industrials | D34: 0 | E34: 580.23267 | F34: 0 | G34: 0 | H34: 3.699432 | I34: 0 | J34: =SUM(E34:I34) -> 583.9321 | K34: =D34+J34 -> 583.9321 | L34: =K34/'Quellen & Annahmen'!$B$2 -> 0.0052891974 | M34: boerse.de-Aktienfonds; MSCI World | N34: https://www.boerse-aktienfonds.de/; https://www.ishares.com/ch/individual/en/products/251882/ishares-msci-world-ucits-etf-acc-fund
A35: 34 | B35: Danaher | C35: Health Care | D35: 0 | E35: 573.57091 | F35: 0 | G35: 0 | H35: 4.708368 | I35: 0 | J35: =SUM(E35:I35) -> 578.27928 | K35: =D35+J35 -> 578.27928 | L35: =K35/'Quellen & Annahmen'!$B$2 -> 0.0052379947 | M35: boerse.de-Aktienfonds; MSCI World | N35: https://www.boerse-aktienfonds.de/; https://www.ishares.com/ch/individual/en/products/251882/ishares-msci-world-ucits-etf-acc-fund
A36: 35 | B36: Hannover Rück | D36: 0 | E36: 577.23593 | F36: 0 | G36: 0 | H36: 0 | I36: 0 | J36: =SUM(E36:I36) -> 577.23593 | K36: =D36+J36 -> 577.23593 | L36: =K36/'Quellen & Annahmen'!$B$2 -> 0.0052285442 | M36: boerse.de-Aktienfonds | N36: https://www.boerse-aktienfonds.de/
A37: 36 | B37: Deutsche Börse | C37: Financials | D37: 0 | E37: 573.61707 | F37: 0 | G37: 0 | H37: 2.017872 | I37: 0 | J37: =SUM(E37:I37) -> 575.63494 | K37: =D37+J37 -> 575.63494 | L37: =K37/'Quellen & Annahmen'!$B$2 -> 0.0052140426 | M37: boerse.de-Aktienfonds; MSCI World | N37: https://www.boerse-aktienfonds.de/; https://www.ishares.com/ch/individual/en/products/251882/ishares-msci-world-ucits-etf-acc-fund
A38: 37 | B38: Walmart | C38: Consumer Staples | D38: 0 | E38: 551.96007 | F38: 0 | G38: 0 | H38: 18.833472 | I38: 0 | J38: =SUM(E38:I38) -> 570.79355 | K38: =D38+J38 -> 570.79355 | L38: =K38/'Quellen & Annahmen'!$B$2 -> 0.0051701897 | M38: boerse.de-Aktienfonds; MSCI World | N38: https://www.boerse-aktienfonds.de/; https://www.ishares.com/ch/individual/en/products/251882/ishares-msci-world-ucits-etf-acc-fund
A39: 38 | B39: Yum! Brands | C39: Consumer Discretionary | D39: 0 | E39: 565.36064 | F39: 0 | G39: 0 | H39: 1.68156 | I39: 0 | J39: =SUM(E39:I39) -> 567.0422 | K39: =D39+J39 -> 567.0422 | L39: =K39/'Quellen & Annahmen'!$B$2 -> 0.0051362104 | M39: boerse.de-Aktienfonds; MSCI World | N39: https://www.boerse-aktienfonds.de/; https://www.ishares.com/ch/individual/en/products/251882/ishares-msci-world-ucits-etf-acc-fund
A40: 39 | B40: TJX Companies | C40: Consumer Discretionary | D40: 0 | E40: 555.88134 | F40: 0 | G40: 0 | H40: 6.389928 | I40: 0 | J40: =SUM(E40:I40) -> 562.27127 | K40: =D40+J40 -> 562.27127 | L40: =K40/'Quellen & Annahmen'!$B$2 -> 0.0050929958 | M40: boerse.de-Aktienfonds; MSCI World | N40: https://www.boerse-aktienfonds.de/; https://www.ishares.com/ch/individual/en/products/251882/ishares-msci-world-ucits-etf-acc-fund
...

Sheet Quellpositionen
A1: Quelle | B1: Holdings-Stichtag | C1: Ticker | D1: Wertpapiername Original | E1: Unternehmen konsolidiert | F1: Sektor | G1: Asset Class | H1: Gewicht im Instrument (%) | I1: Anteil am Depot (€) | J1: Offizielle Quelle
A2: Direktbestand | B2: 17.07.2026 | D2: AMD | E2: AMD | G2: Equity | H2: 100 | I2: 3896.55 | J2: Nutzerangaben im Chat
A3: Direktbestand | B3: 17.07.2026 | D3: Allianz | E3: Allianz | G3: Equity | H3: 100 | I3: 4210 | J3: Nutzerangaben im Chat
A4: Direktbestand | B4: 17.07.2026 | D4: Alphabet C (Google) | E4: Alphabet | G4: Equity | H4: 100 | I4: 3328.6 | J4: Nutzerangaben im Chat
A5: Direktbestand | B5: 17.07.2026 | D5: Apple | E5: Apple | G5: Equity | H5: 100 | I5: 1458.25 | J5: Nutzerangaben im Chat
A6: Direktbestand | B6: 17.07.2026 | D6: Berkshire Hathaway B | E6: Berkshire Hathaway | G6: Equity | H6: 100 | I6: 23600.5 | J6: Nutzerangaben im Chat
A7: Direktbestand | B7: 17.07.2026 | D7: Eli Lilly and Company | E7: Eli Lilly | G7: Equity | H7: 100 | I7: 2060.8 | J7: Nutzerangaben im Chat
A8: Direktbestand | B8: 17.07.2026 | D8: HSBC | E8: HSBC | G8: Equity | H8: 100 | I8: 1702.16 | J8: Nutzerangaben im Chat
A9: Direktbestand | B9: 17.07.2026 | D9: Linde | E9: Linde | G9: Equity | H9: 100 | I9: 896.8 | J9: Nutzerangaben im Chat
A10: Direktbestand | B10: 17.07.2026 | D10: Micron Technology | E10: Micron Technology | G10: Equity | H10: 100 | I10: 1492.2 | J10: Nutzerangaben im Chat
A11: Direktbestand | B11: 17.07.2026 | D11: Microsoft | E11: Microsoft | G11: Equity | H11: 100 | I11: 2410.1 | J11: Nutzerangaben im Chat
A12: Direktbestand | B12: 17.07.2026 | D12: Nvidia | E12: Nvidia | G12: Equity | H12: 100 | I12: 4430.5 | J12: Nutzerangaben im Chat
A13: Direktbestand | B13: 17.07.2026 | D13: Siemens | E13: Siemens | G13: Equity | H13: 100 | I13: 1851.5 | J13: Nutzerangaben im Chat
A14: Direktbestand | B14: 17.07.2026 | D14: TSMC Taiwan Semiconductor (ADR) | E14: TSMC | G14: Equity | H14: 100 | I14: 696 | J14: Nutzerangaben im Chat
A15: Global Titans 50 | B15: 16.07.2026 | C15: ABT | D15: ABBOTT LABORATORIES | E15: Abbott Laboratories | F15: Health Care | G15: Equity | H15: 0.51 | I15: 67.856316 | J15: https://www.ishares.com/ch/professionals/en/products/251769/ishares-dow-jones-global-titans-50-ucits-etf-de-fund
A16: Global Titans 50 | B16: 16.07.2026 | C16: ABBV | D16: ABBVIE INC | E16: Abbvie Inc | F16: Health Care | G16: Equity | H16: 1.32 | I16: 175.62811 | J16: https://www.ishares.com/ch/professionals/en/products/251769/ishares-dow-jones-global-titans-50-ucits-etf-de-fund
A17: Global Titans 50 | B17: 16.07.2026 | C17: ACN | D17: ACCENTURE PLC CLASS A | E17: Accenture Plc | F17: Information Technology | G17: Equity | H17: 0.26 | I17: 34.593416 | J17: https://www.ishares.com/ch/professionals/en/products/251769/ishares-dow-jones-global-titans-50-ucits-etf-de-fund
A18: Global Titans 50 | B18: 16.07.2026 | C18: GOOGL | D18: ALPHABET INC CLASS A | E18: Alphabet | F18: Communication | G18: Equity | H18: 4.27 | I18: 568.13033 | J18: https://www.ishares.com/ch/professionals/en/products/251769/ishares-dow-jones-global-titans-50-ucits-etf-de-fund
A19: Global Titans 50 | B19: 16.07.2026 | C19: GOOG | D19: ALPHABET INC CLASS C | E19: Alphabet | F19: Communication | G19: Equity | H19: 3.43 | I19: 456.36699 | J19: https://www.ishares.com/ch/professionals/en/products/251769/ishares-dow-jones-global-titans-50-ucits-etf-de-fund
A20: Global Titans 50 | B20: 16.07.2026 | C20: AMZN | D20: AMAZON.COM INC | E20: Amazon | F20: Consumer Discretionary | G20: Equity | H20: 7.21 | I20: 959.30204 | J20: https://www.ishares.com/ch/professionals/en/products/251769/ishares-dow-jones-global-titans-50-ucits-etf-de-fund
A21: Global Titans 50 | B21: 16.07.2026 | C21: AAPL | D21: APPLE INC | E21: Apple | F21: Information Technology | G21: Equity | H21: 8.82 | I21: 1173.5151 | J21: https://www.ishares.com/ch/professionals/en/products/251769/ishares-dow-jones-global-titans-50-ucits-etf-de-fund
A22: Global Titans 50 | B22: 16.07.2026 | C22: ASML | D22: ASML HOLDING NV | E22: ASML | F22: Information Technology | G22: Equity | H22: 2.09 | I22: 278.07784 | J22: https://www.ishares.com/ch/professionals/en/products/251769/ishares-dow-jones-global-titans-50-ucits-etf-de-fund
A23: Global Titans 50 | B23: 16.07.2026 | C23: AZN | D23: ASTRAZENECA PLC | E23: Astrazeneca Plc | F23: Health Care | G23: Equity | H23: 0.78 | I23: 103.78025 | J23: https://www.ishares.com/ch/professionals/en/products/251769/ishares-dow-jones-global-titans-50-ucits-etf-de-fund
A24: Global Titans 50 | B24: 16.07.2026 | C24: AVGO | D24: BROADCOM INC | E24: Broadcom | F24: Information Technology | G24: Equity | H24: 5.22 | I24: 694.52935 | J24: https://www.ishares.com/ch/professionals/en/products/251769/ishares-dow-jones-global-titans-50-ucits-etf-de-fund
A25: Global Titans 50 | B25: 16.07.2026 | C25: CAT | D25: CATERPILLAR INC | E25: Caterpillar | F25: Industrials | G25: Equity | H25: 1.19 | I25: 158.3314 | J25: https://www.ishares.com/ch/professionals/en/products/251769/ishares-dow-jones-global-titans-50-ucits-etf-de-fund
A26: Global Titans 50 | B26: 16.07.2026 | C26: CVX | D26: CHEVRON CORP | E26: Chevron Corp | F26: Energy | G26: Equity | H26: 1.01 | I26: 134.38212 | J26: https://www.ishares.com/ch/professionals/en/products/251769/ishares-dow-jones-global-titans-50-ucits-etf-de-fund
... A1749: World Value | B1749: 16.07.2026 | C1749: ZM | D1749: ZOOM COMMUNICATIONS INC CLASS A | E1749: Zoom Communications Inc | F1749: Information Technology | G1749: Equity | H1749: 0.22 | I1749: 2.510288 | J1749: https://www.ishares.com/ch/individual/en/products/270048/ishares-msci-world-value-factor-ucits-etf
A1750: boerse.de-Aktienfonds | B1750: 10.07.2026 | D1750: AMD | E1750: AMD | G1750: Equity | H1750: 2.5439597 | I1750: 573.30194 | J1750: https://www.boerse-aktienfonds.de/
A1751: boerse.de-Aktienfonds | B1751: 10.07.2026 | D1751: ASML | E1751: ASML | G1751: Equity | H1751: 2.4327025 | I1751: 548.22921 | J1751: https://www.boerse-aktienfonds.de/
A1752: boerse.de-Aktienfonds | B1752: 10.07.2026 | D1752: Allianz | E1752: Allianz | G1752: Equity | H1752: 2.5439319 | I1752: 573.29566 | J1752: https://www.boerse-aktienfonds.de/
A1753: boerse.de-Aktienfonds | B1753: 10.07.2026 | D1753: Alphabet | E1753: Alphabet | G1753: Equity | H1753: 2.4631112 | I1753: 555.08205 | J1753: https://www.boerse-aktienfonds.de/
A1754: boerse.de-Aktienfonds | B1754: 10.07.2026 | D1754: Amazon | E1754: Amazon | G1754: Equity | H1754: 2.5197583 | I1754: 567.84793 | J1754: https://www.boerse-aktienfonds.de/
A1755: boerse.de-Aktienfonds | B1755: 10.07.2026 | D1755: Amphenol | E1755: Amphenol | G1755: Equity | H1755: 2.3590347 | I1755: 531.62759 | J1755: https://www.boerse-aktienfonds.de/
A1756: boerse.de-Aktienfonds | B1756: 10.07.2026 | D1756: Apple | E1756: Apple | G1756: Equity | H1756: 2.7295429 | I1756: 615.1246 | J1756: https://www.boerse-aktienfonds.de/
A1757: boerse.de-Aktienfonds | B1757: 10.07.2026 | D1757: AutoZone | E1757: Autozone | G1757: Equity | H1757: 2.4027193 | I1757: 541.47225 | J1757: https://www.boerse-aktienfonds.de/
A1758: boerse.de-Aktienfonds | B1758: 10.07.2026 | D1758: Berkshire Hathaway | E1758: Berkshire Hathaway | G1758: Equity | H1758: 2.4537752 | I1758: 552.97811 | J1758: https://www.boerse-aktienfonds.de/
A1759: boerse.de-Aktienfonds | B1759: 10.07.2026 | D1759: BlackRock | E1759: BlackRock | G1759: Equity | H1759: 2.6567487 | I1759: 598.71983 | J1759: https://www.boerse-aktienfonds.de/
A1760: boerse.de-Aktienfonds | B1760: 10.07.2026 | D1760: Booking Holdings | E1760: Booking Holdings | G1760: Equity | H1760: 2.4103647 | I1760: 543.19522 | J1760: https://www.boerse-aktienfonds.de/
A1761: boerse.de-Aktienfonds | B1761: 10.07.2026 | D1761: Caterpillar | E1761: Caterpillar | G1761: Equity | H1761: 2.2826275 | I1761: 514.4086 | J1761: https://www.boerse-aktienfonds.de/
... A1823: boerse.de-Technologiefonds – Basisportfolio | B1823: 16.07.2026 | D1823: Texas Instruments | E1823: Texas Instruments | G1823: Equity | H1823: 1.729718 | I1823: 81.886234 | J1823: https://www.boerse-technologiefonds.de/

Sheet Direktbestand
A1: Unternehmen konsolidiert | B1: Wertpapier | C1: WKN | D1: ISIN | E1: Stückzahl | F1: Kurs (€) | G1: Aktueller Wert (€) | H1: Stand
A2: Berkshire Hathaway | B2: Berkshire Hathaway B | C2: A0YJQ2 | D2: US0846707026 | E2: 55 | F2: 429.1 | G2: 23600.5 | H2: 17.07.2026
A3: Allianz | B3: Allianz | C3: 840400 | D3: DE0008404005 | E3: 10 | F3: 421 | G3: 4210 | H3: 17.07.2026
A4: Nvidia | B4: Nvidia | C4: 918422 | D4: US67066G1040 | E4: 25 | F4: 177.22 | G4: 4430.5 | H4: 17.07.2026
A5: AMD | B5: AMD | C5: 863186 | D5: US0079031078 | E5: 9 | F5: 432.95 | G5: 3896.55 | H5: 17.07.2026
A6: Alphabet | B6: Alphabet C (Google) | C6: A14Y6H | D6: US02079K1079 | E6: 11 | F6: 302.6 | G6: 3328.6 | H6: 17.07.2026
A7: Micron Technology | B7: Micron Technology | C7: 869020 | D7: US5951121038 | E7: 2 | F7: 746.1 | G7: 1492.2 | H7: 17.07.2026
A8: Microsoft | B8: Microsoft | C8: 870747 | D8: US5949181045 | E8: 7 | F8: 344.3 | G8: 2410.1 | H8: 17.07.2026
A9: Eli Lilly | B9: Eli Lilly and Company | C9: 858560 | D9: US5324571083 | E9: 2 | F9: 1030.4 | G9: 2060.8 | H9: 17.07.2026
A10: Siemens | B10: Siemens | C10: 723610 | D10: DE0007236101 | E10: 7 | F10: 264.5 | G10: 1851.5 | H10: 17.07.2026
A11: HSBC | B11: HSBC | C11: 923893 | D11: GB0005405286 | E11: 97 | F11: 17.55 | G11: 1702.16 | H11: 17.07.2026
A12: Apple | B12: Apple | C12: 865985 | D12: US0378331005 | E12: 5 | F12: 291.65 | G12: 1458.25 | H12: 17.07.2026
A13: Linde | B13: Linde | C13: A3D7VW | D13: IE000S9YS762 | E13: 2 | F13: 448.4 | G13: 896.8 | H13: 17.07.2026
A14: TSMC | B14: TSMC Taiwan Semiconductor (ADR) | C14: 909800 | D14: US8740391003 | E14: 2 | F14: 348 | G14: 696 | H14: 17.07.2026

Sheet Quellen & Annahmen
A1: Quellen, Annahmen und Auflösungsgrad
A2: Gesamtvermögen (€) | B2: 110400.89
A4: Instrument | B4: Depotwert (€) | C4: Depotstand | D4: Holdings-Stichtag | E4: Öffentlich auflösbarer Anteil | F4: Aufgelöster Betrag (€) | G4: Nicht aufgelöst / Nicht-Aktien (€) | H4: Methode / Hinweis | I4: Offizielle Quelle
A5: Direktbestand | B5: 52033.96 | C5: 17.07.2026 | D5: 17.07.2026 | E5: 1 | F5: 52033.96 | G5: 0 | H5: Direkte Nutzerangaben; vollständig berücksichtigt. | I5: Nutzerangaben im Chat
A6: boerse.de-Aktienfonds | B6: 22535.81 | C6: 17.07.2026 | D6: 10.07.2026 | E6: 1 | F6: 22535.81 | G6: 0 | H6: 40 veröffentlichte Aktien nach ihren Marktwerten gewichtet und auf das Aktienportfolio normiert. | I6: https://www.boerse-aktienfonds.de/
A7: Global Titans 50 | B7: 13305.16 | C7: 17.07.2026 | D7: 16.07.2026 | E7: 0.9975 | F7: 13271.897 | G7: 33.2629 | H7: Alle in der offiziellen iShares-Datei als Equity klassifizierten Positionen. | I7: https://www.ishares.com/ch/professionals/en/products/251769/ishares-dow-jones-global-titans-50-ucits-etf-de-fund
A8: boerse.de-Technologiefonds | B8: 4734.08 | C8: 17.07.2026 | D8: 16.07.2026 | E8: 0.6 | F8: 2840.448 | G8: 1893.632 | H8: Nur das vollständig veröffentlichte 60%-Basisportfolio. Das 40%-Darwin-Portfolio (>500 Aktien) ist nicht vollständig öffentlich auflösbar. | I8: https://www.boerse-technologiefonds.de/
A9: MSCI World | B9: 3363.12 | C9: 17.07.2026 | D9: 16.07.2026 | E9: 0.9982 | F9: 3357.0664 | G9: 6.053616 | H9: Alle in der offiziellen iShares-Datei als Equity klassifizierten Positionen. | I9: https://www.ishares.com/ch/individual/en/products/251882/ishares-msci-world-ucits-etf-acc-fund
A10: World Value | B10: 1141.04 | C10: 17.07.2026 | D10: 16.07.2026 | E10: 0.9949 | F10: 1135.2207 | G10: 5.819304 | H10: Alle in der offiziellen iShares-Datei als Equity klassifizierten Positionen. | I10: https://www.ishares.com/ch/individual/en/products/270048/ishares-msci-world-value-factor-ucits-etf
A11: Xetra Gold | B11: 6988.64 | C11: 17.07.2026 | D11: - | E11: 0 | F11: 0 | G11: 6988.64 | H11: Gold-ETC; keine Einzelaktien. | I11: Nutzerangaben im Chat
A12: WisdomTree Physical Bitcoin | B12: 799.08 | C12: 17.07.2026 | D12: - | E12: 0 | F12: 0 | G12: 799.08 | H12: Bitcoin-ETP; keine Einzelaktien. | I12: Nutzerangaben im Chat
A13: Bargeld | B13: 5500 | C13: 17.07.2026 | D13: - | E13: 0 | F13: 0 | G13: 5500 | H13: Bargeld; keine Einzelaktien. | I13: Nutzerangaben im Chat
A15: Kontrollsumme Gesamtvermögen | B15: =SUM(B5:B13) -> 110400.89 | F15: =SUM(F5:F13) -> 95174.402 | G15: =SUM(G5:G13) -> 15226.488
